<?xml version="1.0" ?>
<!-- =================================================================================== -->
<!-- |    This document was autogenerated by xacro from dashgobase.xacro               | -->
<!-- |    EDITING THIS FILE BY HAND IS NOT RECOMMENDED                                 | -->
<!-- =================================================================================== -->
<robot name="box_robot" xmlns:xacro="http://ros.org/wiki/xacro">
  <!--base_height/2+torso_height/2 -->
  <!-- Put all the color definitions in a separate file -->
  <material name="Black">
    <color rgba="0.2 0.2 0.2 1.0"/>
  </material>
  <material name="TransparentBlack">
    <color rgba="0.2 0.2 0.2 0.8"/>
  </material>
  <material name="Orange">
    <color rgba="1.0  0.55 0.0 1.0"/>
  </material>
  <material name="Grey">
    <color rgba="0.7 0.7 0.7 1.0"/>
  </material>
  <material name="DarkGrey">
    <color rgba="0.3 0.3 0.3 1.0"/>
  </material>
  <material name="Red">
    <color rgba="0.8 0.0 0.0 1.0"/>
  </material>
  <material name="White">
    <color rgba="1.0 1.0 1.0 1.0"/>
  </material>
  <material name="OffWhite">
    <color rgba="0.8 0.8 0.8 1.0"/>
  </material>
  <material name="Blue">
    <color rgba="0.0 0.0 0.8 1.0"/>
  </material>
  <material name="Green">
    <color rgba="0.0 0.8 0.0 1.0"/>
  </material>
  <material name="TransparentGreen">
    <color rgba="0.0 0.8 0.0 0.5"/>
  </material>
  <link name="base_footprint">
    <visual>
      <origin rpy="0 0 0" xyz="0 0 0"/>
      <geometry>
        <box size="0.05 0.05 0.001"/>
      </geometry>
      <material name="TransparentGreen"/>
    </visual>
  </link>
  <joint name="base_joint" type="fixed">
    <!--
    <origin xyz="0 0 0.04" rpy="0 0 0" />     
-->
    <origin rpy="0 0 0" xyz="0 0 0.138"/>
    <parent link="base_footprint"/>
    <child link="base_link"/>
  </joint>
  <joint name="base_l_wheel_joint" type="continuous">
    <axis xyz="0 0 1"/>
    <limit effort="100" velocity="100"/>
    <safety_controller k_velocity="10"/>
    <origin rpy="1.5707963 0 0" xyz="-0.095 0.21 -0.038"/>
    <parent link="base_link"/>
    <child link="base_l_wheel_link"/>
  </joint>
  <link name="base_l_wheel_link">
    <!--
 <visual>
<origin xyz=" 0 0 0 " rpy="0 0 0" />
      <geometry>
        <mesh
          filename="package://common/urdf/meshes/wheel.STL" />
      </geometry>
      <material name="${color}" />
</visual>
-->
    <visual>
      <origin rpy="0 0 0" xyz="0 0 0"/>
      <geometry>
        <cylinder length="0.046" radius="0.0801"/>
      </geometry>
      <material name="Orange"/>
    </visual>
  </link>
  <joint name="base_r_wheel_joint" type="continuous">
    <axis xyz="0 0 1"/>
    <limit effort="100" velocity="100"/>
    <safety_controller k_velocity="10"/>
    <origin rpy="-1.5707963 0 0" xyz="-0.095 -0.21 -0.038"/>
    <parent link="base_link"/>
    <child link="base_r_wheel_link"/>
  </joint>
  <link name="base_r_wheel_link">
    <!--
 <visual>
<origin xyz=" 0 0 0 " rpy="0 0 0" />
      <geometry>
        <mesh
          filename="package://common/urdf/meshes/wheel.STL" />
      </geometry>
      <material name="${color}" />
</visual>
-->
    <visual>
      <origin rpy="0 0 0" xyz="0 0 0"/>
      <geometry>
        <cylinder length="0.046" radius="0.0801"/>
      </geometry>
      <material name="Orange"/>
    </visual>
  </link>
  <link name="base_link">
    <!--
 <visual>
<origin xyz=" 0 0 0 " rpy="0 0 0" />
      <geometry>
        <mesh
          filename="package://common/urdf/meshes/dash_base_all.STL" />
      </geometry>
      <material name="">        
        <color
          rgba="255 215 0 0.5"/>
      </material>
</visual>
-->
    <visual>
      <origin rpy="0 0 0" xyz="0 0 0"/>
      <geometry>
        <box size="0.4 0.52 0.2"/>
      </geometry>
      <material name="iRobot/LightGrey"/>
    </visual>
    <collision>
      <origin rpy="0 0 0" xyz="0 0 0"/>
      <geometry>
        <box size="0.4 0.52 0.2"/>
      </geometry>
    </collision>
  </link>
  <!-- Attach the torso -->
  <!--
   <torso name="torso" parent="base" color="Grey">
      <origin xyz="${torso_offset_x} ${torso_offset_y} ${torso_offset_z}" rpy="0 0 0" />
   </torso>
-->
  <!--
 <joint name="laser" type="fixed">
    <origin xyz="0.15 0.00 0.20" rpy="0 0 0" />
    <parent link="base_link" />
    <child link="base_laser_link" />
  </joint>

  <link name="base_laser_link">
    <visual>
      <geometry>
        <box size="0.00 0.05 0.06" />
      </geometry>
      <material name="Green" />
    </visual>
    <inertial>
      <mass value="0.000001" />
      <origin xyz="0 0 0" />
      <inertia ixx="0.0001" ixy="0.0" ixz="0.0"
        iyy="0.0001" iyz="0.0"
        izz="0.0001" />
    </inertial>
  </link>
-->
  <link name="front_flag">
    <visual>
      <origin rpy="0 0 0" xyz="0 0 0"/>
      <geometry>
        <!--
          <box size="0.08 0.08 0.001" />
-->
        <cylinder length="0.05" radius="0.08"/>
      </geometry>
      <material name="TransparentGreen"/>
    </visual>
  </link>
  <joint name="front_point_flag" type="fixed">
    <origin rpy="0 0 0" xyz="0.2 0 0.1"/>
    <parent link="base_link"/>
    <child link="front_flag"/>
  </joint>
</robot>

